Workbook

Sheet 电表
A1: 日期 | B1: 表号 | C1: 表数 | D1: 单价（含税）
A2: 43723 | B2: 1 | C2: 0 | D2: 1.3
A3: 43723 | B3: 2 | C3: 0 | D3: 1.3
A4: 43723 | B4: 3 | C4: 0 | D4: 1.3
A5: 44118 | B5: 1 | C5: 42 | D5: 1.3
A6: 44118 | B6: 2 | C6: 64 | D6: 1.3
A7: 44118 | B7: 3 | C7: 0 | D7: 1.3
A8: 44294 | B8: 1 | C8: 149 | D8: 1.3
A9: 44294 | B9: 2 | C9: 167 | D9: 1.3
A10: 44294 | B10: 3 | C10: 0 | D10: 1.3
A11: 44435 | B11: 1 | C11: 263 | D11: 1.3
A12: 44435 | B12: 2 | C12: 393 | D12: 1.3
A13: 44435 | B13: 3 | C13: 82 | D13: 1.3
... A61: 44927 | B61: 2 | C61: 1508 | D61: 0.95514659
A62: 44958 | B62: 3 | C62: 3534 | D62: =106361.85/103095 -> 1.0316878
A63: 44958 | B63: 1 | C63: 773 | D63: =106361.85/103095 -> 1.0316878
A64: 44958 | B64: 2 | C64: 1604 | D64: =106361.85/103095 -> 1.0316878
A65: 44958 | B65: 祺电调整 | C65: 8400 | D65: =106361.85/103095 -> 1.0316878
A66: 44958 | B66: 吉电调整 | C66: -8400 | D66: =106361.85/103095 -> 1.0316878
A67: 44986 | B67: 2 | C67: 1680 | D67: 0.98873126
A68: 44986 | B68: 1 | C68: 803 | D68: 0.98873126
A69: 44986 | B69: 3 | C69: 3766 | D69: 0.98873126
A70: 44986 | B70: 祺电调整 | C70: 13457 | D70: 0.98873126
A71: 44986 | B71: 吉电调整 | C71: =+-1*C70 -> -13457 | D71: 0.98873126
A72: 45017 | B72: 2 | C72: 1750 | D72: 0.98761739
A73: 45017 | B73: 1 | C73: 827 | D73: 0.98761739
A74: 45017 | B74: 3 | C74: 3953 | D74: 0.98761739
A75: 45017 | B75: 祺电调整 | C75: =13457+5640 -> 19097 | D75: 0.98761739
A76: 45017 | B76: 吉电调整 | C76: =+-1*C75 -> -19097 | D76: 0.98761739
A77: 45047 | B77: 2 | C77: 1820 | D77: =99701.71/95040 -> 1.04905
A78: 45047 | B78: 1 | C78: 847 | D78: =99701.71/95040 -> 1.04905
A79: 45047 | B79: 3 | C79: 4158 | D79: =99701.71/95040 -> 1.04905
A80: 45047 | B80: 祺电调整 | C80: =13457+5640+3995 -> 23092 | D80: =99701.71/95040 -> 1.04905
A81: 45047 | B81: 吉电调整 | C81: =+-1*C80 -> -23092 | D81: =99701.71/95040 -> 1.04905
A82: 45078 | B82: 2 | C82: 1916 | D82: =108245.88/108645 -> 0.99632638
A83: 45078 | B83: 1 | C83: 871 | D83: =108245.88/108645 -> 0.99632638
A84: 45078 | B84: 3 | C84: 4372 | D84: =108245.88/108645 -> 0.99632638
A85: 45078 | B85: 祺电调整 | C85: =13457+5640+3995+7000 -> 30092 | D85: =108245.88/108645 -> 0.99632638
A86: 45078 | B86: 吉电调整 | C86: =+-1*C85 -> -30092 | D86: =108245.88/108645 -> 0.99632638
A87: 45108 | B87: 祺电调整 | C87: =13457+5640+3995+7000+4952.92 -> 35044.92 | D87: =132709.59/131460 -> 1.0095055
...

Sheet 水表
A1: 日期 | B1: 表号 | C1: 表数 | D1: 单价（含税）
A2: 43723 | B2: 1 | C2: 1009 | D2: 6.07
A3: 43723 | B3: 2 | C3: 0 | D3: 6.07
A4: 44118 | B4: 1 | C4: 1125 | D4: 6.07
A5: 44118 | B5: 2 | C5: 0 | D5: 6.07
A6: 44294 | B6: 1 | C6: 1270 | D6: 6.07
A7: 44435 | B7: 1 | C7: 1651 | D7: 6.07
A8: 44435 | B8: 2 | C8: 19 | D8: 6.07
A9: 44479 | B9: 2 | C9: 56 | D9: 5.85
A10: 44479 | B10: 1 | C10: 1734 | D10: 5.85
A11: 44510 | B11: 2 | C11: 86 | D11: 7.9
A12: 44510 | B12: 1 | C12: 1820 | D12: 7.9
A13: 44540 | B13: 2 | C13: 120 | D13: 7.9
... A24: 44682 | B24: 2 | C24: 488 | D24: 7.9
A25: 44713 | B25: 1 | C25: 2478 | D25: =7.9+1.4 -> 9.3
A26: 44713 | B26: 2 | C26: 565 | D26: =7.9+1.4 -> 9.3
A27: 44743 | B27: 1 | C27: 2530 | D27: =7.9+1.4 -> 9.3
A28: 44743 | B28: 2 | C28: 636 | D28: =7.9+1.4 -> 9.3
A29: 44774 | B29: 1 | C29: 2592 | D29: =7.9+1.4 -> 9.3
A30: 44774 | B30: 2 | C30: 757 | D30: =7.9+1.4 -> 9.3
A31: 44805 | B31: 1 | C31: 2641 | D31: =7.9+1.4 -> 9.3
A32: 44805 | B32: 2 | C32: 831 | D32: =7.9+1.4 -> 9.3
A33: 44835 | B33: 1 | C33: 2681 | D33: =7.9+1.4 -> 9.3
A34: 44835 | B34: 2 | C34: 927 | D34: =7.9+1.4 -> 9.3
A35: 44866 | B35: 1 | C35: 2729 | D35: =7.9+1.4 -> 9.3
A36: 44866 | B36: 2 | C36: 988 | D36: =7.9+1.4 -> 9.3
... A42: 44958 | B42: 1 | C42: 2982 | D42: =7.9+1.4 -> 9.3
A43: 44958 | B43: 祺水调整 | C43: 37.5 | D43: =7.9+1.4 -> 9.3
A44: 44958 | B44: 吉水调整 | C44: -37.5 | D44: =7.9+1.4 -> 9.3
A45: 44986 | B45: 1 | C45: 3053 | D45: =7.9+1.4 -> 9.3
A46: 44986 | B46: 2 | C46: 1079 | D46: =7.9+1.4 -> 9.3
A47: 44986 | B47: 祺水调整 | C47: 73 | D47: =7.9+1.4 -> 9.3
A48: 44986 | B48: 吉水调整 | C48: =+-1*C47 -> -73 | D48: =7.9+1.4 -> 9.3
A49: 45017 | B49: 1 | C49: 3153 | D49: =7.9+1.4 -> 9.3
A50: 45017 | B50: 2 | C50: 1097 | D50: =7.9+1.4 -> 9.3
A51: 45017 | B51: 祺水调整 | C51: =73+80 -> 153 | D51: =7.9+1.4 -> 9.3
A52: 45017 | B52: 吉水调整 | C52: =+-1*C51 -> -153 | D52: =7.9+1.4 -> 9.3
A53: 45047 | B53: 1 | C53: 3221 | D53: =7.9+1.4 -> 9.3
A54: 45047 | B54: 2 | C54: 1119 | D54: =7.9+1.4 -> 9.3
A55: 45047 | B55: 祺水调整 | C55: =73+80 -> 153 | D55: =7.9+1.4 -> 9.3
...

Sheet 倍率
A1: 表号 | B1: 倍率
A2: 1 | B2: 120
A3: 2 | B3: 120
A4: 3 | B4: 80
A5: 4 | B5: 40
A6: 10 | B6: 1
A7: 吉电调整 | B7: 1
A8: 吉水调整 | B8: 1
A9: 祺电调整 | B9: 1
A10: 祺水调整 | B10: 1
A11: 4号表调整 | B11: 1

Sheet 祺富单证
A1: 天津祺富机械加工有限公司
A2: 物业明细（单价含税）
A3: 上期日期 | B3: 46204 | C3: 本期日期 | D3: =DATE(YEAR(B3),MONTH(B3)+1,1) -> 46235 | F3: 核定日期 | G3: =DATE(YEAR(B3),MONTH(B3)+1,1) -> 46235
A4: 电费
A5: 表号 | B5: 上期表数 | C5: 本期表数 | D5: 本期用电 | E5: 倍率 | F5: 核定度数 | G5: 单价 | H5: 总价
A6: 3 | B6: =SUMIFS(电表!$C:$C,电表!$B:$B,祺富单证!$A6,电表!$A:$A,祺富单证!$B$3) -> 10457 | C6: =SUMIFS(电表!$C:$C,电表!$B:$B,祺富单证!$A6,电表!$A:$A,祺富单证!$D$3) -> 10606 | D6: =+C6-B6 -> 149 | E6: =SUMIFS(倍率!$B:$B,倍率!$A:$A,祺富单证!$A6) -> 80 | F6: =+E6*D6 -> 11920 | G6: =SUMIFS(电表!$D:$D,电表!$B:$B,祺富单证!$A6,电表!$A:$A,祺富单证!$D$3) -> 1.1957111 | H6: =ROUND(G6*F6,0) -> 14253
A7: 祺电调整 | B7: =SUMIFS(电表!$C:$C,电表!$B:$B,祺富单证!$A7,电表!$A:$A,祺富单证!$B$3) -> 165455.99 | C7: =SUMIFS(电表!$C:$C,电表!$B:$B,祺富单证!$A7,电表!$A:$A,祺富单证!$D$3) -> 172146.57 | D7: =+C7-B7 -> 6690.579 | E7: =SUMIFS(倍率!$B:$B,倍率!$A:$A,祺富单证!$A7) -> 1 | F7: =+E7*D7 -> 6690.579 | G7: =SUMIFS(电表!$D:$D,电表!$B:$B,祺富单证!$A7,电表!$A:$A,祺富单证!$D$3) -> 1.1957111 | H7: =ROUND(G7*F7,0) -> 8000
A8: 合计 | D8: =SUM(D6:D7) -> 6839.579 | F8: =SUM(F6:F7) -> 18610.579 | H8: =SUM(H6:H7) -> 22253
A10: 水费
A11: 表号 | B11: 上期表数 | C11: 本期表数 | D11: 本期用水 | E11: 倍率 | F11: 核定m³ | G11: 单价 | H11: 总价
A12: 2 | B12: =SUMIFS(水表!$C:$C,水表!$B:$B,祺富单证!$A12,水表!$A:$A,祺富单证!$B$3) -> 1963 | C12: =SUMIFS(水表!$C:$C,水表!$B:$B,祺富单证!$A12,水表!$A:$A,祺富单证!$D$3) -> 1967 | D12: =+C12-B12 -> 4 | E12: 1 | F12: =+E12*D12 -> 4 | G12: =SUMIFS(水表!$D:$D,水表!$B:$B,祺富单证!$A12,水表!$A:$A,祺富单证!$D$3) -> 8.3746781 | H12: =ROUND(G12*F12,0) -> 33
A13: 3 | B13: =SUMIFS(水表!$C:$C,水表!$B:$B,祺富单证!$A13,水表!$A:$A,祺富单证!$B$3) -> 0 | C13: =SUMIFS(水表!$C:$C,水表!$B:$B,祺富单证!$A13,水表!$A:$A,祺富单证!$D$3) -> 0 | D13: =+C13-B13 -> 0 | E13: 1 | F13: =+E13*D13 -> 0 | G13: =SUMIFS(水表!$D:$D,水表!$B:$B,祺富单证!$A13,水表!$A:$A,祺富单证!$D$3) -> 8.3746781 | H13: =ROUND(G13*F13,0) -> 0
A14: 祺水调整 | B14: =SUMIFS(水表!$C:$C,水表!$B:$B,祺富单证!$A14,水表!$A:$A,祺富单证!$B$3) -> 2007.9622 | C14: =SUMIFS(水表!$C:$C,水表!$B:$B,祺富单证!$A14,水表!$A:$A,祺富单证!$D$3) -> 2127.3698 | D14: =+C14-B14 -> 119.4076 | E14: 1 | F14: =+E14*D14 -> 119.4076 | G14: =SUMIFS(水表!$D:$D,水表!$B:$B,祺富单证!$A14,水表!$A:$A,祺富单证!$D$3) -> 8.3746781 | H14: =ROUND(G14*F14,0) -> 1000
A15: 合计 | D15: =SUM(D12:D14) -> 123.4076 | F15: =SUM(F12:F14) -> 123.4076 | H15: =SUM(H12:H14) -> 1033
A17: 祺富合计水电费
A18: 项目 | B18: 金额 | C18: 税率 | D18: 税额 | E18: 合计 | F18: 数量 | G18: 单价 | H18: 水电费合计
A19: 电费 | B19: =+E19-D19 -> 19692.92 | C19: 0.13 | D19: =E19-E19/(C19+1) -> 2560.0796 | E19: =+H8 -> 22253 | F19: =+F8 -> 18610.579 | G19: =+E19/F19 -> 1.1957178 | H19: =+E19+E20 -> 23286
A20: 水费 | B20: =+E20-D20 -> 947.70642 | C20: 0.09 | D20: =E20-E20/(C20+1) -> 85.293578 | E20: =+H15 -> 1033 | F20: =+F15 -> 123.4076 | G20: =+E20/F20 -> 8.3706352

Sheet 吉众单证
A1: 天津吉众科技有限公司
A2: 物业明细（单价含税）
A3: 上期日期 | B3: =祺富单证!B3 -> 46204 | C3: 本期日期 | D3: =+祺富单证!D3 -> 46235 | F3: 核定日期 | G3: =+祺富单证!G3 -> 46235
A4: 电费
A5: 表号 | B5: 上期表数 | C5: 本期表数 | D5: 本期用电 | E5: 倍率 | F5: 核定度数 | G5: 单价 | H5: 总价
A6: 1 | B6: =SUMIFS(电表!$C:$C,电表!$B:$B,吉众单证!$A6,电表!$A:$A,吉众单证!$B$3) -> 2711 | C6: =SUMIFS(电表!$C:$C,电表!$B:$B,吉众单证!$A6,电表!$A:$A,吉众单证!$D$3) -> 2780 | D6: =+C6-B6 -> 69 | E6: =SUMIFS(倍率!$B:$B,倍率!$A:$A,吉众单证!$A6) -> 120 | F6: =+E6*D6 -> 8280 | G6: =SUMIFS(电表!$D:$D,电表!$B:$B,吉众单证!$A6,电表!$A:$A,吉众单证!$D$3) -> 1.1957111 | H6: =ROUND(G6*F6,0) -> 9900
A7: 2 | B7: =SUMIFS(电表!$C:$C,电表!$B:$B,吉众单证!$A7,电表!$A:$A,吉众单证!$B$3) -> 6967 | C7: =SUMIFS(电表!$C:$C,电表!$B:$B,吉众单证!$A7,电表!$A:$A,吉众单证!$D$3) -> 7150 | D7: =+C7-B7 -> 183 | E7: =SUMIFS(倍率!$B:$B,倍率!$A:$A,吉众单证!$A7) -> 120 | F7: =+E7*D7 -> 21960 | G7: =SUMIFS(电表!$D:$D,电表!$B:$B,吉众单证!$A7,电表!$A:$A,吉众单证!$D$3) -> 1.1957111 | H7: =ROUND(G7*F7,0) -> 26258
A8: 4 | B8: =SUMIFS(电表!$C:$C,电表!$B:$B,吉众单证!$A8,电表!$A:$A,吉众单证!$B$3) -> 624 | C8: =SUMIFS(电表!$C:$C,电表!$B:$B,吉众单证!$A8,电表!$A:$A,吉众单证!$D$3) -> 631 | D8: =+C8-B8 -> 7 | E8: =SUMIFS(倍率!$B:$B,倍率!$A:$A,吉众单证!$A8) -> 40 | F8: =+E8*D8 -> 280 | G8: =SUMIFS(电表!$D:$D,电表!$B:$B,吉众单证!$A8,电表!$A:$A,吉众单证!$D$3) -> 1.1957111 | H8: =ROUND(G8*F8,0) -> 335
A9: 4号表调整 | B9: 0 | C9: =SUMIFS(电表!$C:$C,电表!$B:$B,吉众单证!$A9,电表!$A:$A,吉众单证!$D$3) -> -100 | D9: =+C9-B9 -> -100 | E9: =SUMIFS(倍率!$B:$B,倍率!$A:$A,吉众单证!$A9) -> 1 | F9: =+E9*D9 -> -100 | G9: =SUMIFS(电表!$D:$D,电表!$B:$B,吉众单证!$A9,电表!$A:$A,吉众单证!$D$3) -> 1.1957111 | H9: =ROUND(G9*F9,0) -> -120
A10: 表合计 | D10: =+SUM(D6:D7) -> 252 | F10: =+SUM(F6:F9) -> 30420 | H10: =+SUM(H6:H9) -> 36373
A11: 吉电调整 | B11: =SUMIFS(电表!$C:$C,电表!$B:$B,吉众单证!$A11,电表!$A:$A,吉众单证!$B$3) -> -165455.99 | C11: =SUMIFS(电表!$C:$C,电表!$B:$B,吉众单证!$A11,电表!$A:$A,吉众单证!$D$3) -> -172146.57 | D11: =+C11-B11 -> -6690.579 | E11: =SUMIFS(倍率!$B:$B,倍率!$A:$A,吉众单证!$A11) -> 1 | F11: =+E11*D11 -> -6690.579 | G11: =SUMIFS(电表!$D:$D,电表!$B:$B,吉众单证!$A11,电表!$A:$A,吉众单证!$D$3) -> 1.1957111 | H11: =ROUND(G11*F11,0) -> -8000
A12: 合计 | D12: =SUM(D6:D8)+D11 -> -6431.579 | F12: =F10+F11 -> 23729.421 | H12: =H10+H11 -> 28373
A14: 水费
A15: 表号 | B15: 上期表数 | C15: 本期表数 | D15: 本期用水 | E15: 倍率 | F15: 核定m³ | G15: 单价 | H15: 总价
A16: 1 | B16: =SUMIFS(水表!$C:$C,水表!$B:$B,吉众单证!$A16,水表!$A:$A,吉众单证!$B$3) -> 10356 | C16: =SUMIFS(水表!$C:$C,水表!$B:$B,吉众单证!$A16,水表!$A:$A,吉众单证!$D$3) -> 10644 | D16: =+C16-B16 -> 288 | E16: 1 | F16: =+E16*D16 -> 288 | G16: =SUMIFS(水表!$D:$D,水表!$B:$B,吉众单证!$A16,水表!$A:$A,吉众单证!$D$3) -> 8.3746781 | H16: =ROUND(G16*F16,0) -> 2412
A17: 4 | B17: =SUMIFS(水表!$C:$C,水表!$B:$B,吉众单证!$A17,水表!$A:$A,吉众单证!$B$3) -> 12 | C17: =SUMIFS(水表!$C:$C,水表!$B:$B,吉众单证!$A17,水表!$A:$A,吉众单证!$D$3) -> 12 | D17: =+C17-B17 -> 0 | E17: 1 | F17: =+E17*D17 -> 0 | G17: =SUMIFS(水表!$D:$D,水表!$B:$B,吉众单证!$A17,水表!$A:$A,吉众单证!$D$3) -> 8.3746781 | H17: =ROUND(G17*F17,0) -> 0
A18: 5 | B18: =SUMIFS(水表!$C:$C,水表!$B:$B,吉众单证!$A18,水表!$A:$A,吉众单证!$B$3) -> 2 | C18: =SUMIFS(水表!$C:$C,水表!$B:$B,吉众单证!$A18,水表!$A:$A,吉众单证!$D$3) -> 2 | D18: =+C18-B18 -> 0 | E18: 1 | F18: =+E18*D18 -> 0 | G18: =SUMIFS(水表!$D:$D,水表!$B:$B,吉众单证!$A18,水表!$A:$A,吉众单证!$D$3) -> 8.3746781 | H18: =ROUND(G18*F18,0) -> 0
A19: 吉水调整 | B19: =SUMIFS(水表!$C:$C,水表!$B:$B,吉众单证!$A19,水表!$A:$A,吉众单证!$B$3) -> -2007.9622 | C19: =SUMIFS(水表!$C:$C,水表!$B:$B,吉众单证!$A19,水表!$A:$A,吉众单证!$D$3) -> -2127.3698 | D19: =+C19-B19 -> -119.4076 | E19: 1 | F19: =+E19*D19 -> -119.4076 | G19: =SUMIFS(水表!$D:$D,水表!$B:$B,吉众单证!$A19,水表!$A:$A,吉众单证!$D$3) -> 8.3746781 | H19: =ROUND(G19*F19,0) -> -1000
A20: 合计 | D20: =SUM(D16:D19) -> 168.5924 | F20: =SUM(F16:F19) -> 168.5924 | H20: =SUM(H16:H19) -> 1412
A22: 吉众合计水电费
A23: 项目 | B23: 金额 | C23: 税率 | D23: 税额 | E23: 合计 | F23: 数量 | G23: 单位 | H23: 水电费合计
A24: 电费 | B24: =+E24-D24 -> 25108.85 | C24: 0.13 | D24: =E24-E24/(C24+1) -> 3264.1504 | E24: =+H12 -> 28373 | F24: =+F12 -> 23729.421 | G24: =+E24/F24 -> 1.1956887 | H24: =+E24+E25 -> 29785
A25: 水费 | B25: =+E25-D25 -> 1295.4128 | C25: 0.09 | D25: =E25-E25/(C25+1) -> 116.58716 | E25: =+H20 -> 1412 | F25: =+F20 -> 168.5924 | G25: =+E25/F25 -> 8.3752293

Sheet 合计单证
A1: 合计
A2: 物业明细（单价含税）
A3: 上期日期 | B3: =+祺富单证!B3 -> 46204 | C3: 本期日期 | D3: =+祺富单证!D3 -> 46235 | F3: 核定日期 | G3: =+祺富单证!G3 -> 46235
A4: 电费
A5: 表号 | B5: 上期表数 | C5: 本期表数 | D5: 本期用电 | E5: 倍率 | F5: 核定度数 | G5: 单价 | H5: 总价
A6: 合计 | F6: =+吉众单证!F12+祺富单证!F8 -> 42340 | G6: =SUMIFS(电表!$D:$D,电表!$B:$B,吉众单证!$A6,电表!$A:$A,吉众单证!$D$3) -> 1.1957111 | H6: =ROUND(G6*F6,0) -> 50626
A7: 合计 | F7: =+F6 -> 42340 | H7: =+H6 -> 50626
A9: 水费
A10: 表号 | B10: 上期表数 | C10: 本期表数 | D10: 本期用水 | E10: 倍率 | F10: 核定m³ | G10: 单价 | H10: 总价
A11: 合计 | D11: =+C11-B11 -> 0 | E11: 1 | F11: =+吉众单证!F20+祺富单证!F15 -> 292 | G11: =SUMIFS(水表!$D:$D,水表!$B:$B,吉众单证!$A16,水表!$A:$A,吉众单证!$D$3) -> 8.3746781 | H11: =ROUND(G11*F11,0) -> 2445
A12: 合计 | D12: =SUM(D11:D11) -> 0 | F12: =SUM(F11:F11) -> 292 | H12: =SUM(H11:H11) -> 2445
A14: 吉众合计水电费
A15: 项目 | B15: 金额 | C15: 税率 | D15: 税额 | E15: 合计 | F15: 数量 | G15: 单位 | H15: 水电费合计
A16: 电费 | B16: =+E16-D16 -> 44801.77 | C16: 0.13 | D16: =E16-E16/(C16+1) -> 5824.2301 | E16: =+H7 -> 50626 | F16: =+F7 -> 42340 | G16: =+E16/F16 -> 1.1957015 | H16: =+E16+E17 -> 53071
A17: 水费 | B17: =+E17-D17 -> 2243.1193 | C17: 0.09 | D17: =E17-E17/(C17+1) -> 201.88073 | E17: =+H12 -> 2445 | F17: =+F12 -> 292 | G17: =+E17/F17 -> 8.3732877

Sheet 合并记录
C1: 吉众 | R1: 祺富
C2: 电表 | K2: 水表 | R2: 电费 | W2: 水费
A3: 日期 | B3: 日期 | C3: 1 | D3: 2 | E3: 4 | F3: 4号表调整 | G3: 吉电调整 | H3: 合计kwh | I3: 单价 | J3: 合计电费 | K3: 1 | L3: 4 | M3: 5 | N3: 吉水调整 | O3: 合计吨 | P3: 单价 | Q3: 合计水费 | R3: 3 | S3: 祺电调整 | T3: 合计kwh | U3: 单价 | V3: 合计电费 | W3: 2 | X3: 3 | Y3: 祺水调整 | Z3: 合计吨 | AA3: 单价 | AB3: 合计水费
A4: 使用月份 | B4: 记账月份 | C4: =SUMIFS(倍率!$B:$B,倍率!$A:$A,吉众单证!$A6) -> 120 | D4: =SUMIFS(倍率!$B:$B,倍率!$A:$A,吉众单证!$A7) -> 120 | E4: =SUMIFS(倍率!$B:$B,倍率!$A:$A,吉众单证!$A8) -> 40 | F4: =SUMIFS(倍率!$B:$B,倍率!$A:$A,吉众单证!$A9) -> 1 | G4: 1 | R4: 80 | S4: 1
A5: 44866 | B5: 44896 | C5: =SUMIFS(电表!$C:$C,电表!$B:$B,C$3,电表!$A:$A,$B5) -> 677 | D5: =SUMIFS(电表!$C:$C,电表!$B:$B,D$3,电表!$A:$A,$B5) -> 1400 | E5: =SUMIFS(电表!$C:$C,电表!$B:$B,E$3,电表!$A:$A,$B5) -> 0 | F5: =SUMIFS(电表!$C:$C,电表!$B:$B,F$3,电表!$A:$A,$B5) -> 0 | G5: =SUMIFS(电表!$C:$C,电表!$B:$B,G$3,电表!$A:$A,$B5) -> 0 | I5: =SUMIFS(电表!$D:$D,电表!$B:$B,C$3,电表!$A:$A,$B4) -> 0 | K5: =SUMIFS(水表!$C:$C,水表!$B:$B,K$3,水表!$A:$A,$B5) -> 2828 | L5: =SUMIFS(水表!$C:$C,水表!$B:$B,L$3,水表!$A:$A,$B5) -> 0 | M5: =SUMIFS(水表!$C:$C,水表!$B:$B,M$3,水表!$A:$A,$B5) -> 0 | N5: =SUMIFS(水表!$C:$C,水表!$B:$B,N$3,水表!$A:$A,$B5) -> 0 | R5: =SUMIFS(电表!$C:$C,电表!$B:$B,R$3,电表!$A:$A,$B5) -> 2868 | S5: =SUMIFS(电表!$C:$C,电表!$B:$B,S$3,电表!$A:$A,$B5) -> 0 | U5: =+I5 -> 0 | V5: =SUMIFS(电表!$C:$C,电表!$B:$B,V$3,电表!$A:$A,$B5) -> 0 | W5: =SUMIFS(水表!$C:$C,水表!$B:$B,W$3,水表!$A:$A,$B5) -> 1007 | X5: =SUMIFS(水表!$C:$C,水表!$B:$B,X$3,水表!$A:$A,$B5) -> 0 | Y5: =SUMIFS(水表!$C:$C,水表!$B:$B,Y$3,水表!$A:$A,$B5) -> 0 | Z5: =SUMIFS(电表!$C:$C,电表!$B:$B,Z$3,电表!$A:$A,$B5) -> 0
A6: =DATE(YEAR(A5), MONTH(A5) + 1, DAY(A5)) -> 44896 | B6: =DATE(YEAR(B5), MONTH(B5) + 1, DAY(B5)) -> 44927 | C6: =SUMIFS(电表!$C:$C,电表!$B:$B,C$3,电表!$A:$A,$B6) -> 729 | D6: =SUMIFS(电表!$C:$C,电表!$B:$B,D$3,电表!$A:$A,$B6) -> 1508 | E6: =SUMIFS(电表!$C:$C,电表!$B:$B,E$3,电表!$A:$A,$B6) -> 0 | F6: =SUMIFS(电表!$C:$C,电表!$B:$B,F$3,电表!$A:$A,$B6) -> 0 | G6: =SUMIFS(电表!$C:$C,电表!$B:$B,G$3,电表!$A:$A,$B6) -> 0 | H6: =+(C6-C5)*C$4+(D6-D5)*D$4+(E6-E5)*E$4+(F6-F5)*F$4+(G6-G5)*G$4 -> 19200 | I6: =SUMIFS(电表!$D:$D,电表!$B:$B,C$3,电表!$A:$A,$B6) -> 0.95514659 | J6: =ROUND(H6*I6,2) -> 18338.81 | K6: =SUMIFS(水表!$C:$C,水表!$B:$B,K$3,水表!$A:$A,$B6) -> 2907 | L6: =SUMIFS(水表!$C:$C,水表!$B:$B,L$3,水表!$A:$A,$B6) -> 0 | M6: =SUMIFS(水表!$C:$C,水表!$B:$B,M$3,水表!$A:$A,$B6) -> 0 | N6: =SUMIFS(水表!$C:$C,水表!$B:$B,N$3,水表!$A:$A,$B6) -> 0 | O6: =+SUM(K6:N6)-SUM(K5:N5) -> 79 | P6: =SUMIFS(水表!$D:$D,水表!$B:$B,K$3,水表!$A:$A,B6) -> 9.3 | Q6: =ROUND(O6*P6,2) -> 734.7 | R6: =SUMIFS(电表!$C:$C,电表!$B:$B,R$3,电表!$A:$A,$B6) -> 3288 | S6: =SUMIFS(电表!$C:$C,电表!$B:$B,S$3,电表!$A:$A,$B6) -> 0 | T6: =IF(SUM(R6)<=0,0,(R6-R5)*R$4+(S6-S5)*S$4) -> 33600 | U6: =+I6 -> 0.95514659 | V6: =ROUND(T6*U6,2) -> 32092.93 | W6: =SUMIFS(水表!$C:$C,水表!$B:$B,W$3,水表!$A:$A,$B6) -> 1031 | X6: =SUMIFS(水表!$C:$C,水表!$B:$B,X$3,水表!$A:$A,$B6) -> 0 | Y6: =SUMIFS(水表!$C:$C,水表!$B:$B,Y$3,水表!$A:$A,$B6) -> 0 | Z6: =+SUM(W6:Y6)-SUM(W5:Y5) -> 24 | AA6: =+P6 -> 9.3 | AB6: =ROUND(Z6*AA6,2) -> 223.2
A7: =DATE(YEAR(A6), MONTH(A6) + 1, DAY(A6)) -> 44927 | B7: =DATE(YEAR(B6), MONTH(B6) + 1, DAY(B6)) -> 44958 | C7: =SUMIFS(电表!$C:$C,电表!$B:$B,C$3,电表!$A:$A,$B7) -> 773 | D7: =SUMIFS(电表!$C:$C,电表!$B:$B,D$3,电表!$A:$A,$B7) -> 1604 | E7: =SUMIFS(电表!$C:$C,电表!$B:$B,E$3,电表!$A:$A,$B7) -> 0 | F7: =SUMIFS(电表!$C:$C,电表!$B:$B,F$3,电表!$A:$A,$B7) -> 0 | G7: =SUMIFS(电表!$C:$C,电表!$B:$B,G$3,电表!$A:$A,$B7) -> -8400 | H7: =+(C7-C6)*C$4+(D7-D6)*D$4+(E7-E6)*E$4+(F7-F6)*F$4+(G7-G6)*G$4 -> 8400 | I7: =SUMIFS(电表!$D:$D,电表!$B:$B,C$3,电表!$A:$A,$B7) -> 1.0316878 | J7: =ROUND(H7*I7,2) -> 8666.18 | K7: =SUMIFS(水表!$C:$C,水表!$B:$B,K$3,水表!$A:$A,$B7) -> 2982 | L7: =SUMIFS(水表!$C:$C,水表!$B:$B,L$3,水表!$A:$A,$B7) -> 0 | M7: =SUMIFS(水表!$C:$C,水表!$B:$B,M$3,水表!$A:$A,$B7) -> 0 | N7: =SUMIFS(水表!$C:$C,水表!$B:$B,N$3,水表!$A:$A,$B7) -> -37.5 | O7: =+SUM(K7:N7)-SUM(K6:N6) -> 37.5 | P7: =SUMIFS(水表!$D:$D,水表!$B:$B,K$3,水表!$A:$A,B7) -> 9.3 | Q7: =ROUND(O7*P7,2) -> 348.75 | R7: =SUMIFS(电表!$C:$C,电表!$B:$B,R$3,电表!$A:$A,$B7) -> 3534 | S7: =SUMIFS(电表!$C:$C,电表!$B:$B,S$3,电表!$A:$A,$B7) -> 8400 | T7: =IF(SUM(R7)<=0,0,(R7-R6)*R$4+(S7-S6)*S$4) -> 28080 | U7: =+I7 -> 1.0316878 | V7: =ROUND(T7*U7,2) -> 28969.79 | W7: =SUMIFS(水表!$C:$C,水表!$B:$B,W$3,水表!$A:$A,$B7) -> 1051 | X7: =SUMIFS(水表!$C:$C,水表!$B:$B,X$3,水表!$A:$A,$B7) -> 0 | Y7: =SUMIFS(水表!$C:$C,水表!$B:$B,Y$3,水表!$A:$A,$B7) -> 37.5 | Z7: =+SUM(W7:Y7)-SUM(W6:Y6) -> 57.5 | AA7: =+P7 -> 9.3 | AB7: =ROUND(Z7*AA7,2) -> 534.75
A8: =DATE(YEAR(A7), MONTH(A7) + 1, DAY(A7)) -> 44958 | B8: =DATE(YEAR(B7), MONTH(B7) + 1, DAY(B7)) -> 44986 | C8: =SUMIFS(电表!$C:$C,电表!$B:$B,C$3,电表!$A:$A,$B8) -> 803 | D8: =SUMIFS(电表!$C:$C,电表!$B:$B,D$3,电表!$A:$A,$B8) -> 1680 | E8: =SUMIFS(电表!$C:$C,电表!$B:$B,E$3,电表!$A:$A,$B8) -> 0 | F8: =SUMIFS(电表!$C:$C,电表!$B:$B,F$3,电表!$A:$A,$B8) -> 0 | G8: =SUMIFS(电表!$C:$C,电表!$B:$B,G$3,电表!$A:$A,$B8) -> -13457 | H8: =+(C8-C7)*C$4+(D8-D7)*D$4+(E8-E7)*E$4+(F8-F7)*F$4+(G8-G7)*G$4 -> 7663 | I8: =SUMIFS(电表!$D:$D,电表!$B:$B,C$3,电表!$A:$A,$B8) -> 0.98873126 | J8: =ROUND(H8*I8,2) -> 7576.65 | K8: =SUMIFS(水表!$C:$C,水表!$B:$B,K$3,水表!$A:$A,$B8) -> 3053 | L8: =SUMIFS(水表!$C:$C,水表!$B:$B,L$3,水表!$A:$A,$B8) -> 0 | M8: =SUMIFS(水表!$C:$C,水表!$B:$B,M$3,水表!$A:$A,$B8) -> 0 | N8: =SUMIFS(水表!$C:$C,水表!$B:$B,N$3,水表!$A:$A,$B8) -> -73 | O8: =+SUM(K8:N8)-SUM(K7:N7) -> 35.5 | P8: =SUMIFS(水表!$D:$D,水表!$B:$B,K$3,水表!$A:$A,B8) -> 9.3 | Q8: =ROUND(O8*P8,2) -> 330.15 | R8: =SUMIFS(电表!$C:$C,电表!$B:$B,R$3,电表!$A:$A,$B8) -> 3766 | S8: =SUMIFS(电表!$C:$C,电表!$B:$B,S$3,电表!$A:$A,$B8) -> 13457 | T8: =IF(SUM(R8)<=0,0,(R8-R7)*R$4+(S8-S7)*S$4) -> 23617 | U8: =+I8 -> 0.98873126 | V8: =ROUND(T8*U8,2) -> 23350.87 | W8: =SUMIFS(水表!$C:$C,水表!$B:$B,W$3,水表!$A:$A,$B8) -> 1079 | X8: =SUMIFS(水表!$C:$C,水表!$B:$B,X$3,水表!$A:$A,$B8) -> 0 | Y8: =SUMIFS(水表!$C:$C,水表!$B:$B,Y$3,水表!$A:$A,$B8) -> 73 | Z8: =+SUM(W8:Y8)-SUM(W7:Y7) -> 63.5 | AA8: =+P8 -> 9.3 | AB8: =ROUND(Z8*AA8,2) -> 590.55
A9: =DATE(YEAR(A8), MONTH(A8) + 1, DAY(A8)) -> 44986 | B9: =DATE(YEAR(B8), MONTH(B8) + 1, DAY(B8)) -> 45017 | C9: =SUMIFS(电表!$C:$C,电表!$B:$B,C$3,电表!$A:$A,$B9) -> 827 | D9: =SUMIFS(电表!$C:$C,电表!$B:$B,D$3,电表!$A:$A,$B9) -> 1750 | E9: =SUMIFS(电表!$C:$C,电表!$B:$B,E$3,电表!$A:$A,$B9) -> 0 | F9: =SUMIFS(电表!$C:$C,电表!$B:$B,F$3,电表!$A:$A,$B9) -> 0 | G9: =SUMIFS(电表!$C:$C,电表!$B:$B,G$3,电表!$A:$A,$B9) -> -19097 | H9: =IF(SUM(C9:E9)<=0,0,(C9-C8)*C$4+(D9-D8)*D$4+(E9-E8)*E$4+(F9-F8)*F$4+(G9-G8)*G$4) -> 5640 | I9: =SUMIFS(电表!$D:$D,电表!$B:$B,C$3,电表!$A:$A,$B9) -> 0.98761739 | J9: =ROUND(H9*I9,2) -> 5570.16 | K9: =SUMIFS(水表!$C:$C,水表!$B:$B,K$3,水表!$A:$A,$B9) -> 3153 | L9: =SUMIFS(水表!$C:$C,水表!$B:$B,L$3,水表!$A:$A,$B9) -> 0 | M9: =SUMIFS(水表!$C:$C,水表!$B:$B,M$3,水表!$A:$A,$B9) -> 0 | N9: =SUMIFS(水表!$C:$C,水表!$B:$B,N$3,水表!$A:$A,$B9) -> -153 | O9: =IF(SUM(K9:M9)<=0,0,SUM(K9:N9)-SUM(K8:N8)) -> 20 | P9: =SUMIFS(水表!$D:$D,水表!$B:$B,K$3,水表!$A:$A,B9) -> 9.3 | Q9: =ROUND(O9*P9,2) -> 186 | R9: =SUMIFS(电表!$C:$C,电表!$B:$B,R$3,电表!$A:$A,$B9) -> 3953 | S9: =SUMIFS(电表!$C:$C,电表!$B:$B,S$3,电表!$A:$A,$B9) -> 19097 | T9: =IF(SUM(R9)<=0,0,(R9-R8)*R$4+(S9-S8)*S$4) -> 20600 | U9: =+I9 -> 0.98761739 | V9: =ROUND(T9*U9,2) -> 20344.92 | W9: =SUMIFS(水表!$C:$C,水表!$B:$B,W$3,水表!$A:$A,$B9) -> 1097 | X9: =SUMIFS(水表!$C:$C,水表!$B:$B,X$3,水表!$A:$A,$B9) -> 0 | Y9: =SUMIFS(水表!$C:$C,水表!$B:$B,Y$3,水表!$A:$A,$B9) -> 153 | Z9: =IF(SUM(W9:X9)<=0,0,SUM(W9:Y9)-SUM(W8:Y8)) -> 98 | AA9: =+P9 -> 9.3 | AB9: =ROUND(Z9*AA9,2) -> 911.4
A10: =DATE(YEAR(A9), MONTH(A9) + 1, DAY(A9)) -> 45017 | B10: =DATE(YEAR(B9), MONTH(B9) + 1, DAY(B9)) -> 45047 | C10: =SUMIFS(电表!$C:$C,电表!$B:$B,C$3,电表!$A:$A,$B10) -> 847 | D10: =SUMIFS(电表!$C:$C,电表!$B:$B,D$3,电表!$A:$A,$B10) -> 1820 | E10: =SUMIFS(电表!$C:$C,电表!$B:$B,E$3,电表!$A:$A,$B10) -> 0 | F10: =SUMIFS(电表!$C:$C,电表!$B:$B,F$3,电表!$A:$A,$B10) -> 0 | G10: =SUMIFS(电表!$C:$C,电表!$B:$B,G$3,电表!$A:$A,$B10) -> -23092 | H10: =IF(SUM(C10:E10)<=0,0,(C10-C9)*C$4+(D10-D9)*D$4+(E10-E9)*E$4+(F10-F9)*F$4+(G10-G9)*G$4) -> 6805 | I10: =SUMIFS(电表!$D:$D,电表!$B:$B,C$3,电表!$A:$A,$B10) -> 1.04905 | J10: =ROUND(H10*I10,2) -> 7138.79 | K10: =SUMIFS(水表!$C:$C,水表!$B:$B,K$3,水表!$A:$A,$B10) -> 3221 | L10: =SUMIFS(水表!$C:$C,水表!$B:$B,L$3,水表!$A:$A,$B10) -> 0 | M10: =SUMIFS(水表!$C:$C,水表!$B:$B,M$3,水表!$A:$A,$B10) -> 0 | N10: =SUMIFS(水表!$C:$C,水表!$B:$B,N$3,水表!$A:$A,$B10) -> -153 | O10: =IF(SUM(K10:M10)<=0,0,SUM(K10:N10)-SUM(K9:N9)) -> 68 | P10: =SUMIFS(水表!$D:$D,水表!$B:$B,K$3,水表!$A:$A,B10) -> 9.3 | Q10: =ROUND(O10*P10,2) -> 632.4 | R10: =SUMIFS(电表!$C:$C,电表!$B:$B,R$3,电表!$A:$A,$B10) -> 4158 | S10: =SUMIFS(电表!$C:$C,电表!$B:$B,S$3,电表!$A:$A,$B10) -> 23092 | T10: =IF(SUM(R10)<=0,0,(R10-R9)*R$4+(S10-S9)*S$4) -> 20395 | U10: =+I10 -> 1.04905 | V10: =ROUND(T10*U10,2) -> 21395.37 | W10: =SUMIFS(水表!$C:$C,水表!$B:$B,W$3,水表!$A:$A,$B10) -> 1119 | X10: =SUMIFS(水表!$C:$C,水表!$B:$B,X$3,水表!$A:$A,$B10) -> 0 | Y10: =SUMIFS(水表!$C:$C,水表!$B:$B,Y$3,水表!$A:$A,$B10) -> 153 | Z10: =IF(SUM(W10:X10)<=0,0,SUM(W10:Y10)-SUM(W9:Y9)) -> 22 | AA10: =+P10 -> 9.3 | AB10: =ROUND(Z10*AA10,2) -> 204.6
A11: =DATE(YEAR(A10), MONTH(A10) + 1, DAY(A10)) -> 45047 | B11: =DATE(YEAR(B10), MONTH(B10) + 1, DAY(B10)) -> 45078 | C11: =SUMIFS(电表!$C:$C,电表!$B:$B,C$3,电表!$A:$A,$B11) -> 871 | D11: =SUMIFS(电表!$C:$C,电表!$B:$B,D$3,电表!$A:$A,$B11) -> 1916 | E11: =SUMIFS(电表!$C:$C,电表!$B:$B,E$3,电表!$A:$A,$B11) -> 0 | F11: =SUMIFS(电表!$C:$C,电表!$B:$B,F$3,电表!$A:$A,$B11) -> 0 | G11: =SUMIFS(电表!$C:$C,电表!$B:$B,G$3,电表!$A:$A,$B11) -> -30092 | H11: =IF(SUM(C11:E11)<=0,0,(C11-C10)*C$4+(D11-D10)*D$4+(E11-E10)*E$4+(F11-F10)*F$4+(G11-G10)*G$4) -> 7400 | I11: =SUMIFS(电表!$D:$D,电表!$B:$B,C$3,电表!$A:$A,$B11) -> 0.99632638 | J11: =ROUND(H11*I11,2) -> 7372.82 | K11: =SUMIFS(水表!$C:$C,水表!$B:$B,K$3,水表!$A:$A,$B11) -> 3341 | L11: =SUMIFS(水表!$C:$C,水表!$B:$B,L$3,水表!$A:$A,$B11) -> 0 | M11: =SUMIFS(水表!$C:$C,水表!$B:$B,M$3,水表!$A:$A,$B11) -> 0 | N11: =SUMIFS(水表!$C:$C,水表!$B:$B,N$3,水表!$A:$A,$B11) -> -213 | O11: =IF(SUM(K11:M11)<=0,0,SUM(K11:N11)-SUM(K10:N10)) -> 60 | P11: =SUMIFS(水表!$D:$D,水表!$B:$B,K$3,水表!$A:$A,B11) -> 9.3 | Q11: =ROUND(O11*P11,2) -> 558 | R11: =SUMIFS(电表!$C:$C,电表!$B:$B,R$3,电表!$A:$A,$B11) -> 4372 | S11: =SUMIFS(电表!$C:$C,电表!$B:$B,S$3,电表!$A:$A,$B11) -> 30092 | T11: =IF(SUM(R11)<=0,0,(R11-R10)*R$4+(S11-S10)*S$4) -> 24120 | U11: =+I11 -> 0.99632638 | V11: =ROUND(T11*U11,2) -> 24031.39 | W11: =SUMIFS(水表!$C:$C,水表!$B:$B,W$3,水表!$A:$A,$B11) -> 1162 | X11: =SUMIFS(水表!$C:$C,水表!$B:$B,X$3,水表!$A:$A,$B11) -> 0 | Y11: =SUMIFS(水表!$C:$C,水表!$B:$B,Y$3,水表!$A:$A,$B11) -> 213 | Z11: =IF(SUM(W11:X11)<=0,0,SUM(W11:Y11)-SUM(W10:Y10)) -> 103 | AA11: =+P11 -> 9.3 | AB11: =ROUND(Z11*AA11,2) -> 957.9
A12: =DATE(YEAR(A11), MONTH(A11) + 1, DAY(A11)) -> 45078 | B12: =DATE(YEAR(B11), MONTH(B11) + 1, DAY(B11)) -> 45108 | C12: =SUMIFS(电表!$C:$C,电表!$B:$B,C$3,电表!$A:$A,$B12) -> 890 | D12: =SUMIFS(电表!$C:$C,电表!$B:$B,D$3,电表!$A:$A,$B12) -> 1985 | E12: =SUMIFS(电表!$C:$C,电表!$B:$B,E$3,电表!$A:$A,$B12) -> 0 | F12: =SUMIFS(电表!$C:$C,电表!$B:$B,F$3,电表!$A:$A,$B12) -> 0 | G12: =SUMIFS(电表!$C:$C,电表!$B:$B,G$3,电表!$A:$A,$B12) -> -35044.92 | H12: =IF(SUM(C12:E12)<=0,0,(C12-C11)*C$4+(D12-D11)*D$4+(E12-E11)*E$4+(F12-F11)*F$4+(G12-G11)*G$4) -> 5607.08 | I12: =SUMIFS(电表!$D:$D,电表!$B:$B,C$3,电表!$A:$A,$B12) -> 1.0095055 | J12: =ROUND(H12*I12,2) -> 5660.38 | K12: =SUMIFS(水表!$C:$C,水表!$B:$B,K$3,水表!$A:$A,$B12) -> 3460 | L12: =SUMIFS(水表!$C:$C,水表!$B:$B,L$3,水表!$A:$A,$B12) -> 0 | M12: =SUMIFS(水表!$C:$C,水表!$B:$B,M$3,水表!$A:$A,$B12) -> 0 | N12: =SUMIFS(水表!$C:$C,水表!$B:$B,N$3,水表!$A:$A,$B12) -> -263 | O12: =IF(SUM(K12:M12)<=0,0,SUM(K12:N12)-SUM(K11:N11)) -> 69 | P12: =SUMIFS(水表!$D:$D,水表!$B:$B,K$3,水表!$A:$A,B12) -> 9.3 | Q12: =ROUND(O12*P12,2) -> 641.7 | R12: =SUMIFS(电表!$C:$C,电表!$B:$B,R$3,电表!$A:$A,$B12) -> 4600 | S12: =SUMIFS(电表!$C:$C,电表!$B:$B,S$3,电表!$A:$A,$B12) -> 35044.92 | T12: =IF(SUM(R12)<=0,0,(R12-R11)*R$4+(S12-S11)*S$4) -> 23192.92 | U12: =+I12 -> 1.0095055 | V12: =ROUND(T12*U12,2) -> 23413.38 | W12: =SUMIFS(水表!$C:$C,水表!$B:$B,W$3,水表!$A:$A,$B12) -> 1202 | X12: =SUMIFS(水表!$C:$C,水表!$B:$B,X$3,水表!$A:$A,$B12) -> 0 | Y12: =SUMIFS(水表!$C:$C,水表!$B:$B,Y$3,水表!$A:$A,$B12) -> 263 | Z12: =IF(SUM(W12:X12)<=0,0,SUM(W12:Y12)-SUM(W11:Y11)) -> 90 | AA12: =+P12 -> 9.3 | AB12: =ROUND(Z12*AA12,2) -> 837
A13: =DATE(YEAR(A12), MONTH(A12) + 1, DAY(A12)) -> 45108 | B13: =DATE(YEAR(B12), MONTH(B12) + 1, DAY(B12)) -> 45139 | C13: =SUMIFS(电表!$C:$C,电表!$B:$B,C$3,电表!$A:$A,$B13) -> 914 | D13: =SUMIFS(电表!$C:$C,电表!$B:$B,D$3,电表!$A:$A,$B13) -> 2069 | E13: =SUMIFS(电表!$C:$C,电表!$B:$B,E$3,电表!$A:$A,$B13) -> 0 | F13: =SUMIFS(电表!$C:$C,电表!$B:$B,F$3,电表!$A:$A,$B13) -> 0 | G13: =SUMIFS(电表!$C:$C,电表!$B:$B,G$3,电表!$A:$A,$B13) -> -40139.92 | H13: =IF(SUM(C13:E13)<=0,0,(C13-C12)*C$4+(D13-D12)*D$4+(E13-E12)*E$4+(F13-F12)*F$4+(G13-G12)*G$4) -> 7865 | I13: =SUMIFS(电表!$D:$D,电表!$B:$B,C$3,电表!$A:$A,$B13) -> 0.98142553 | J13: =ROUND(H13*I13,2) -> 7718.91 | K13: =SUMIFS(水表!$C:$C,水表!$B:$B,K$3,水表!$A:$A,$B13) -> 3530 | L13: =SUMIFS(水表!$C:$C,水表!$B:$B,L$3,水表!$A:$A,$B13) -> 0 | M13: =SUMIFS(水表!$C:$C,水表!$B:$B,M$3,水表!$A:$A,$B13) -> 0 | N13: =SUMIFS(水表!$C:$C,水表!$B:$B,N$3,水表!$A:$A,$B13) -> -263 | O13: =IF(SUM(K13:M13)<=0,0,SUM(K13:N13)-SUM(K12:N12)) -> 70 | P13: =SUMIFS(水表!$D:$D,水表!$B:$B,K$3,水表!$A:$A,B13) -> 9.3 | Q13: =ROUND(O13*P13,2) -> 651 | R13: =SUMIFS(电表!$C:$C,电表!$B:$B,R$3,电表!$A:$A,$B13) -> 4826 | S13: =SUMIFS(电表!$C:$C,电表!$B:$B,S$3,电表!$A:$A,$B13) -> 40139.92 | T13: =IF(SUM(R13)<=0,0,(R13-R12)*R$4+(S13-S12)*S$4) -> 23175 | U13: =+I13 -> 0.98142553 | V13: =ROUND(T13*U13,2) -> 22744.54 | W13: =SUMIFS(水表!$C:$C,水表!$B:$B,W$3,水表!$A:$A,$B13) -> 1270 | X13: =SUMIFS(水表!$C:$C,水表!$B:$B,X$3,水表!$A:$A,$B13) -> 0 | Y13: =SUMIFS(水表!$C:$C,水表!$B:$B,Y$3,水表!$A:$A,$B13) -> 263 | Z13: =IF(SUM(W13:X13)<=0,0,SUM(W13:Y13)-SUM(W12:Y12)) -> 68 | AA13: =+P13 -> 9.3 | AB13: =ROUND(Z13*AA13,2) -> 632.4
A14: =DATE(YEAR(A13), MONTH(A13) + 1, DAY(A13)) -> 45139 | B14: =DATE(YEAR(B13), MONTH(B13) + 1, DAY(B13)) -> 45170 | C14: =SUMIFS(电表!$C:$C,电表!$B:$B,C$3,电表!$A:$A,$B14) -> 944 | D14: =SUMIFS(电表!$C:$C,电表!$B:$B,D$3,电表!$A:$A,$B14) -> 2185 | E14: =SUMIFS(电表!$C:$C,电表!$B:$B,E$3,电表!$A:$A,$B14) -> 0 | F14: =SUMIFS(电表!$C:$C,电表!$B:$B,F$3,电表!$A:$A,$B14) -> 0 | G14: =SUMIFS(电表!$C:$C,电表!$B:$B,G$3,电表!$A:$A,$B14) -> -48878.92 | H14: =IF(SUM(C14:E14)<=0,0,(C14-C13)*C$4+(D14-D13)*D$4+(E14-E13)*E$4+(F14-F13)*F$4+(G14-G13)*G$4) -> 8781 | I14: =SUMIFS(电表!$D:$D,电表!$B:$B,C$3,电表!$A:$A,$B14) -> 0.9727 | J14: =ROUND(H14*I14,2) -> 8541.28 | K14: =SUMIFS(水表!$C:$C,水表!$B:$B,K$3,水表!$A:$A,$B14) -> 3695 | L14: =SUMIFS(水表!$C:$C,水表!$B:$B,L$3,水表!$A:$A,$B14) -> 0 | M14: =SUMIFS(水表!$C:$C,水表!$B:$B,M$3,水表!$A:$A,$B14) -> 0 | N14: =SUMIFS(水表!$C:$C,水表!$B:$B,N$3,水表!$A:$A,$B14) -> -363 | O14: =IF(SUM(K14:M14)<=0,0,SUM(K14:N14)-SUM(K13:N13)) -> 65 | P14: =SUMIFS(水表!$D:$D,水表!$B:$B,K$3,水表!$A:$A,B14) -> 9.3 | Q14: =ROUND(O14*P14,2) -> 604.5 | R14: =SUMIFS(电表!$C:$C,电表!$B:$B,R$3,电表!$A:$A,$B14) -> 5045 | S14: =SUMIFS(电表!$C:$C,电表!$B:$B,S$3,电表!$A:$A,$B14) -> 48878.92 | T14: =IF(SUM(R14)<=0,0,(R14-R13)*R$4+(S14-S13)*S$4) -> 26259 | U14: =+I14 -> 0.9727 | V14: =ROUND(T14*U14,2) -> 25542.13 | W14: =SUMIFS(水表!$C:$C,水表!$B:$B,W$3,水表!$A:$A,$B14) -> 1295 | X14: =SUMIFS(水表!$C:$C,水表!$B:$B,X$3,水表!$A:$A,$B14) -> 0 | Y14: =SUMIFS(水表!$C:$C,水表!$B:$B,Y$3,水表!$A:$A,$B14) -> 363 | Z14: =IF(SUM(W14:X14)<=0,0,SUM(W14:Y14)-SUM(W13:Y13)) -> 125 | AA14: =+P14 -> 9.3 | AB14: =ROUND(Z14*AA14,2) -> 1162.5
A15: =DATE(YEAR(A14), MONTH(A14) + 1, DAY(A14)) -> 45170 | B15: =DATE(YEAR(B14), MONTH(B14) + 1, DAY(B14)) -> 45200 | C15: =SUMIFS(电表!$C:$C,电表!$B:$B,C$3,电表!$A:$A,$B15) -> 973 | D15: =SUMIFS(电表!$C:$C,电表!$B:$B,D$3,电表!$A:$A,$B15) -> 2296 | E15: =SUMIFS(电表!$C:$C,电表!$B:$B,E$3,电表!$A:$A,$B15) -> 0 | F15: =SUMIFS(电表!$C:$C,电表!$B:$B,F$3,电表!$A:$A,$B15) -> 0 | G15: =SUMIFS(电表!$C:$C,电表!$B:$B,G$3,电表!$A:$A,$B15) -> -57378.92 | H15: =IF(SUM(C15:E15)<=0,0,(C15-C14)*C$4+(D15-D14)*D$4+(E15-E14)*E$4+(F15-F14)*F$4+(G15-G14)*G$4) -> 8300 | I15: =SUMIFS(电表!$D:$D,电表!$B:$B,C$3,电表!$A:$A,$B15) -> 1.0023 | J15: =ROUND(H15*I15,2) -> 8319.09 | K15: =SUMIFS(水表!$C:$C,水表!$B:$B,K$3,水表!$A:$A,$B15) -> 3848 | L15: =SUMIFS(水表!$C:$C,水表!$B:$B,L$3,水表!$A:$A,$B15) -> 0 | M15: =SUMIFS(水表!$C:$C,水表!$B:$B,M$3,水表!$A:$A,$B15) -> 0 | N15: =SUMIFS(水表!$C:$C,水表!$B:$B,N$3,水表!$A:$A,$B15) -> -463 | O15: =IF(SUM(K15:M15)<=0,0,SUM(K15:N15)-SUM(K14:N14)) -> 53 | P15: =SUMIFS(水表!$D:$D,水表!$B:$B,K$3,水表!$A:$A,B15) -> 9.3 | Q15: =ROUND(O15*P15,2) -> 492.9 | R15: =SUMIFS(电表!$C:$C,电表!$B:$B,R$3,电表!$A:$A,$B15) -> 5274 | S15: =SUMIFS(电表!$C:$C,电表!$B:$B,S$3,电表!$A:$A,$B15) -> 57378.92 | T15: =IF(SUM(R15)<=0,0,(R15-R14)*R$4+(S15-S14)*S$4) -> 26820 | U15: =+I15 -> 1.0023 | V15: =ROUND(T15*U15,2) -> 26881.69 | W15: =SUMIFS(水表!$C:$C,水表!$B:$B,W$3,水表!$A:$A,$B15) -> 1331 | X15: =SUMIFS(水表!$C:$C,水表!$B:$B,X$3,水表!$A:$A,$B15) -> 0 | Y15: =SUMIFS(水表!$C:$C,水表!$B:$B,Y$3,水表!$A:$A,$B15) -> 463 | Z15: =IF(SUM(W15:X15)<=0,0,SUM(W15:Y15)-SUM(W14:Y14)) -> 136 | AA15: =+P15 -> 9.3 | AB15: =ROUND(Z15*AA15,2) -> 1264.8
A16: =DATE(YEAR(A15), MONTH(A15) + 1, DAY(A15)) -> 45200 | B16: =DATE(YEAR(B15), MONTH(B15) + 1, DAY(B15)) -> 45231 | C16: =SUMIFS(电表!$C:$C,电表!$B:$B,C$3,电表!$A:$A,$B16) -> 997 | D16: =SUMIFS(电表!$C:$C,电表!$B:$B,D$3,电表!$A:$A,$B16) -> 2378 | E16: =SUMIFS(电表!$C:$C,电表!$B:$B,E$3,电表!$A:$A,$B16) -> 0 | F16: =SUMIFS(电表!$C:$C,电表!$B:$B,F$3,电表!$A:$A,$B16) -> 0 | G16: =SUMIFS(电表!$C:$C,电表!$B:$B,G$3,电表!$A:$A,$B16) -> -61969.92 | H16: =IF(SUM(C16:E16)<=0,0,(C16-C15)*C$4+(D16-D15)*D$4+(E16-E15)*E$4+(F16-F15)*F$4+(G16-G15)*G$4) -> 8129 | I16: =SUMIFS(电表!$D:$D,电表!$B:$B,C$3,电表!$A:$A,$B16) -> 1.089 | J16: =ROUND(H16*I16,2) -> 8852.48 | K16: =SUMIFS(水表!$C:$C,水表!$B:$B,K$3,水表!$A:$A,$B16) -> 3961 | L16: =SUMIFS(水表!$C:$C,水表!$B:$B,L$3,水表!$A:$A,$B16) -> 0 | M16: =SUMIFS(水表!$C:$C,水表!$B:$B,M$3,水表!$A:$A,$B16) -> 0 | N16: =SUMIFS(水表!$C:$C,水表!$B:$B,N$3,水表!$A:$A,$B16) -> -513 | O16: =IF(SUM(K16:M16)<=0,0,SUM(K16:N16)-SUM(K15:N15)) -> 63 | P16: =SUMIFS(水表!$D:$D,水表!$B:$B,K$3,水表!$A:$A,B16) -> 9.3 | Q16: =ROUND(O16*P16,2) -> 585.9 | R16: =SUMIFS(电表!$C:$C,电表!$B:$B,R$3,电表!$A:$A,$B16) -> 5437 | S16: =SUMIFS(电表!$C:$C,电表!$B:$B,S$3,电表!$A:$A,$B16) -> 61969.92 | T16: =IF(SUM(R16)<=0,0,(R16-R15)*R$4+(S16-S15)*S$4) -> 17631 | U16: =+I16 -> 1.089 | V16: =ROUND(T16*U16,2) -> 19200.16 | W16: =SUMIFS(水表!$C:$C,水表!$B:$B,W$3,水表!$A:$A,$B16) -> 1366 | X16: =SUMIFS(水表!$C:$C,水表!$B:$B,X$3,水表!$A:$A,$B16) -> 0 | Y16: =SUMIFS(水表!$C:$C,水表!$B:$B,Y$3,水表!$A:$A,$B16) -> 513 | Z16: =IF(SUM(W16:X16)<=0,0,SUM(W16:Y16)-SUM(W15:Y15)) -> 85 | AA16: =+P16 -> 9.3 | AB16: =ROUND(Z16*AA16,2) -> 790.5
A17: =DATE(YEAR(A16), MONTH(A16) + 1, DAY(A16)) -> 45231 | B17: =DATE(YEAR(B16), MONTH(B16) + 1, DAY(B16)) -> 45261 | C17: =SUMIFS(电表!$C:$C,电表!$B:$B,C$3,电表!$A:$A,$B17) -> 1024 | D17: =SUMIFS(电表!$C:$C,电表!$B:$B,D$3,电表!$A:$A,$B17) -> 2443 | E17: =SUMIFS(电表!$C:$C,电表!$B:$B,E$3,电表!$A:$A,$B17) -> 0 | F17: =SUMIFS(电表!$C:$C,电表!$B:$B,F$3,电表!$A:$A,$B17) -> 0 | G17: =SUMIFS(电表!$C:$C,电表!$B:$B,G$3,电表!$A:$A,$B17) -> -65969.92 | H17: =IF(SUM(C17:E17)<=0,0,(C17-C16)*C$4+(D17-D16)*D$4+(E17-E16)*E$4+(F17-F16)*F$4+(G17-G16)*G$4) -> 7040 | I17: =SUMIFS(电表!$D:$D,电表!$B:$B,C$3,电表!$A:$A,$B17) -> 1.0588811 | J17: =ROUND(H17*I17,2) -> 7454.52 | K17: =SUMIFS(水表!$C:$C,水表!$B:$B,K$3,水表!$A:$A,$B17) -> 4082 | L17: =SUMIFS(水表!$C:$C,水表!$B:$B,L$3,水表!$A:$A,$B17) -> 0 | M17: =SUMIFS(水表!$C:$C,水表!$B:$B,M$3,水表!$A:$A,$B17) -> 0 | N17: =SUMIFS(水表!$C:$C,水表!$B:$B,N$3,水表!$A:$A,$B17) -> -573 | O17: =IF(SUM(K17:M17)<=0,0,SUM(K17:N17)-SUM(K16:N16)) -> 61 | P17: =SUMIFS(水表!$D:$D,水表!$B:$B,K$3,水表!$A:$A,B17) -> 9.3 | Q17: =ROUND(O17*P17,2) -> 567.3 | R17: =SUMIFS(电表!$C:$C,电表!$B:$B,R$3,电表!$A:$A,$B17) -> 5633 | S17: =SUMIFS(电表!$C:$C,电表!$B:$B,S$3,电表!$A:$A,$B17) -> 65969.92 | T17: =IF(SUM(R17)<=0,0,(R17-R16)*R$4+(S17-S16)*S$4) -> 19680 | U17: =+I17 -> 1.0588811 | V17: =ROUND(T17*U17,2) -> 20838.78 | W17: =SUMIFS(水表!$C:$C,水表!$B:$B,W$3,水表!$A:$A,$B17) -> 1392 | X17: =SUMIFS(水表!$C:$C,水表!$B:$B,X$3,水表!$A:$A,$B17) -> 0 | Y17: =SUMIFS(水表!$C:$C,水表!$B:$B,Y$3,水表!$A:$A,$B17) -> 573 | Z17: =IF(SUM(W17:X17)<=0,0,SUM(W17:Y17)-SUM(W16:Y16)) -> 86 | AA17: =+P17 -> 9.3 | AB17: =ROUND(Z17*AA17,2) -> 799.8
A18: =DATE(YEAR(A17), MONTH(A17) + 1, DAY(A17)) -> 45261 | B18: =DATE(YEAR(B17), MONTH(B17) + 1, DAY(B17)) -> 45292 | C18: =SUMIFS(电表!$C:$C,电表!$B:$B,C$3,电表!$A:$A,$B18) -> 1068 | D18: =SUMIFS(电表!$C:$C,电表!$B:$B,D$3,电表!$A:$A,$B18) -> 2519 | E18: =SUMIFS(电表!$C:$C,电表!$B:$B,E$3,电表!$A:$A,$B18) -> 0 | F18: =SUMIFS(电表!$C:$C,电表!$B:$B,F$3,电表!$A:$A,$B18) -> 0 | G18: =SUMIFS(电表!$C:$C,电表!$B:$B,G$3,电表!$A:$A,$B18) -> -69469.92 | H18: =IF(SUM(C18:E18)<=0,0,(C18-C17)*C$4+(D18-D17)*D$4+(E18-E17)*E$4+(F18-F17)*F$4+(G18-G17)*G$4) -> 10900 | I18: =SUMIFS(电表!$D:$D,电表!$B:$B,C$3,电表!$A:$A,$B18) -> 0.98025953 | J18: =ROUND(H18*I18,2) -> 10684.83 | K18: =SUMIFS(水表!$C:$C,水表!$B:$B,K$3,水表!$A:$A,$B18) -> 4222 | L18: =SUMIFS(水表!$C:$C,水表!$B:$B,L$3,水表!$A:$A,$B18) -> 0 | M18: =SUMIFS(水表!$C:$C,水表!$B:$B,M$3,水表!$A:$A,$B18) -> 0 | N18: =SUMIFS(水表!$C:$C,水表!$B:$B,N$3,水表!$A:$A,$B18) -> -618 | O18: =IF(SUM(K18:M18)<=0,0,SUM(K18:N18)-SUM(K17:N17)) -> 95 | P18: =SUMIFS(水表!$D:$D,水表!$B:$B,K$3,水表!$A:$A,B18) -> 9.3 | Q18: =ROUND(O18*P18,2) -> 883.5 | R18: =SUMIFS(电表!$C:$C,电表!$B:$B,R$3,电表!$A:$A,$B18) -> 5918 | S18: =SUMIFS(电表!$C:$C,电表!$B:$B,S$3,电表!$A:$A,$B18) -> 69469.92 | T18: =IF(SUM(R18)<=0,0,(R18-R17)*R$4+(S18-S17)*S$4) -> 26300 | U18: =+I18 -> 0.98025953 | V18: =ROUND(T18*U18,2) -> 25780.83 | W18: =SUMIFS(水表!$C:$C,水表!$B:$B,W$3,水表!$A:$A,$B18) -> 1424 | X18: =SUMIFS(水表!$C:$C,水表!$B:$B,X$3,水表!$A:$A,$B18) -> 0 | Y18: =SUMIFS(水表!$C:$C,水表!$B:$B,Y$3,水表!$A:$A,$B18) -> 618 | Z18: =IF(SUM(W18:X18)<=0,0,SUM(W18:Y18)-SUM(W17:Y17)) -> 77 | AA18: =+P18 -> 9.3 | AB18: =ROUND(Z18*AA18,2) -> 716.1
A19: =DATE(YEAR(A18), MONTH(A18) + 1, DAY(A18)) -> 45292 | B19: =DATE(YEAR(B18), MONTH(B18) + 1, DAY(B18)) -> 45323 | C19: =SUMIFS(电表!$C:$C,电表!$B:$B,C$3,电表!$A:$A,$B19) -> 1108 | D19: =SUMIFS(电表!$C:$C,电表!$B:$B,D$3,电表!$A:$A,$B19) -> 2607 | E19: =SUMIFS(电表!$C:$C,电表!$B:$B,E$3,电表!$A:$A,$B19) -> 51 | F19: =SUMIFS(电表!$C:$C,电表!$B:$B,F$3,电表!$A:$A,$B19) -> 0 | G19: =SUMIFS(电表!$C:$C,电表!$B:$B,G$3,电表!$A:$A,$B19) -> -69469.92 | H19: =IF(SUM(C19:E19)<=0,0,(C19-C18)*C$4+(D19-D18)*D$4+(E19-E18)*E$4+(F19-F18)*F$4+(G19-G18)*G$4) -> 17400 | I19: =SUMIFS(电表!$D:$D,电表!$B:$B,C$3,电表!$A:$A,$B19) -> 1.0354422 | J19: =ROUND(H19*I19,2) -> 18016.69 | K19: =SUMIFS(水表!$C:$C,水表!$B:$B,K$3,水表!$A:$A,$B19) -> 4452 | L19: =SUMIFS(水表!$C:$C,水表!$B:$B,L$3,水表!$A:$A,$B19) -> 0 | M19: =SUMIFS(水表!$C:$C,水表!$B:$B,M$3,水表!$A:$A,$B19) -> 0 | N19: =SUMIFS(水表!$C:$C,水表!$B:$B,N$3,水表!$A:$A,$B19) -> -718 | O19: =IF(SUM(K19:M19)<=0,0,SUM(K19:N19)-SUM(K18:N18)) -> 130 | P19: =SUMIFS(水表!$D:$D,水表!$B:$B,K$3,水表!$A:$A,B19) -> 9.3 | Q19: =ROUND(O19*P19,2) -> 1209 | R19: =SUMIFS(电表!$C:$C,电表!$B:$B,R$3,电表!$A:$A,$B19) -> 6182 | S19: =SUMIFS(电表!$C:$C,电表!$B:$B,S$3,电表!$A:$A,$B19) -> 69469.92 | T19: =IF(SUM(R19)<=0,0,(R19-R18)*R$4+(S19-S18)*S$4) -> 21120 | U19: =+I19 -> 1.0354422 | V19: =ROUND(T19*U19,2) -> 21868.54 | W19: =SUMIFS(水表!$C:$C,水表!$B:$B,W$3,水表!$A:$A,$B19) -> 1454 | X19: =SUMIFS(水表!$C:$C,水表!$B:$B,X$3,水表!$A:$A,$B19) -> 0 | Y19: =SUMIFS(水表!$C:$C,水表!$B:$B,Y$3,水表!$A:$A,$B19) -> 718 | Z19: =IF(SUM(W19:X19)<=0,0,SUM(W19:Y19)-SUM(W18:Y18)) -> 130 | AA19: =+P19 -> 9.3 | AB19: =ROUND(Z19*AA19,2) -> 1209
A20: =DATE(YEAR(A19), MONTH(A19) + 1, DAY(A19)) -> 45323 | B20: =DATE(YEAR(B19), MONTH(B19) + 1, DAY(B19)) -> 45352 | C20: =SUMIFS(电表!$C:$C,电表!$B:$B,C$3,电表!$A:$A,$B20) -> 1147 | D20: =SUMIFS(电表!$C:$C,电表!$B:$B,D$3,电表!$A:$A,$B20) -> 2717 | E20: =SUMIFS(电表!$C:$C,电表!$B:$B,E$3,电表!$A:$A,$B20) -> 109 | F20: =SUMIFS(电表!$C:$C,电表!$B:$B,F$3,电表!$A:$A,$B20) -> 0 | G20: =SUMIFS(电表!$C:$C,电表!$B:$B,G$3,电表!$A:$A,$B20) -> -71469.92 | H20: =IF(SUM(C20:E20)<=0,0,(C20-C19)*C$4+(D20-D19)*D$4+(E20-E19)*E$4+(F20-F19)*F$4+(G20-G19)*G$4) -> 18200 | I20: =SUMIFS(电表!$D:$D,电表!$B:$B,C$3,电表!$A:$A,$B20) -> 1.14983 | J20: =ROUND(H20*I20,2) -> 20926.91 | K20: =SUMIFS(水表!$C:$C,水表!$B:$B,K$3,水表!$A:$A,$B20) -> 4838 | L20: =SUMIFS(水表!$C:$C,水表!$B:$B,L$3,水表!$A:$A,$B20) -> 0 | M20: =SUMIFS(水表!$C:$C,水表!$B:$B,M$3,水表!$A:$A,$B20) -> 0 | N20: =SUMIFS(水表!$C:$C,水表!$B:$B,N$3,水表!$A:$A,$B20) -> -738 | O20: =IF(SUM(K20:M20)<=0,0,SUM(K20:N20)-SUM(K19:N19)) -> 366 | P20: =SUMIFS(水表!$D:$D,水表!$B:$B,K$3,水表!$A:$A,B20) -> 9.3 | Q20: =ROUND(O20*P20,2) -> 3403.8 | R20: =SUMIFS(电表!$C:$C,电表!$B:$B,R$3,电表!$A:$A,$B20) -> 6346 | S20: =SUMIFS(电表!$C:$C,电表!$B:$B,S$3,电表!$A:$A,$B20) -> 71469.92 | T20: =IF(SUM(R20)<=0,0,(R20-R19)*R$4+(S20-S19)*S$4) -> 15120 | U20: =+I20 -> 1.14983 | V20: =ROUND(T20*U20,2) -> 17385.43 | W20: =SUMIFS(水表!$C:$C,水表!$B:$B,W$3,水表!$A:$A,$B20) -> 1473 | X20: =SUMIFS(水表!$C:$C,水表!$B:$B,X$3,水表!$A:$A,$B20) -> 0 | Y20: =SUMIFS(水表!$C:$C,水表!$B:$B,Y$3,水表!$A:$A,$B20) -> 738 | Z20: =IF(SUM(W20:X20)<=0,0,SUM(W20:Y20)-SUM(W19:Y19)) -> 39 | AA20: =+P20 -> 9.3 | AB20: =ROUND(Z20*AA20,2) -> 362.7
... A47: =DATE(YEAR(A46), MONTH(A46) + 1, DAY(A46)) -> 46143 | B47: =DATE(YEAR(B46), MONTH(B46) + 1, DAY(B46)) -> 46174 | C47: =SUMIFS(电表!$C:$C,电表!$B:$B,C$3,电表!$A:$A,$B47) -> 2640 | D47: =SUMIFS(电表!$C:$C,电表!$B:$B,D$3,电表!$A:$A,$B47) -> 6782 | E47: =SUMIFS(电表!$C:$C,电表!$B:$B,E$3,电表!$A:$A,$B47) -> 618 | F47: =SUMIFS(电表!$C:$C,电表!$B:$B,F$3,电表!$A:$A,$B47) -> -100 | G47: =SUMIFS(电表!$C:$C,电表!$B:$B,G$3,电表!$A:$A,$B47) -> -160281.56 | H47: =IF(SUM(C47:E47)<=0,0,(C47-C46)*C$4+(D47-D46)*D$4+(E47-E46)*E$4+(F47-F46)*F$4+(G47-G46)*G$4) -> 28680 | I47: =SUMIFS(电表!$D:$D,电表!$B:$B,C$3,电表!$A:$A,$B47) -> 1.1317308 | J47: =ROUND(H47*I47,2) -> 32458.04 | K47: =SUMIFS(水表!$C:$C,水表!$B:$B,K$3,水表!$A:$A,$B47) -> 10067 | L47: =SUMIFS(水表!$C:$C,水表!$B:$B,L$3,水表!$A:$A,$B47) -> 12 | M47: =SUMIFS(水表!$C:$C,水表!$B:$B,M$3,水表!$A:$A,$B47) -> 2 | N47: =SUMIFS(水表!$C:$C,水表!$B:$B,N$3,水表!$A:$A,$B47) -> -1910.22 | O47: =IF(SUM(K47:M47)<=0,0,SUM(K47:N47)-SUM(K46:N46)) -> 187 | P47: =SUMIFS(水表!$D:$D,水表!$B:$B,K$3,水表!$A:$A,B47) -> 11.319849 | Q47: =ROUND(O47*P47,2) -> 2116.81 | R47: =SUMIFS(电表!$C:$C,电表!$B:$B,R$3,电表!$A:$A,$B47) -> 10321 | S47: =SUMIFS(电表!$C:$C,电表!$B:$B,S$3,电表!$A:$A,$B47) -> 160281.56 | T47: =IF(SUM(R47)<=0,0,(R47-R46)*R$4+(S47-S46)*S$4) -> 10240 | U47: =+I47 -> 1.1317308 | V47: =ROUND(T47*U47,2) -> 11588.92 | W47: =SUMIFS(水表!$C:$C,水表!$B:$B,W$3,水表!$A:$A,$B47) -> 1959 | X47: =SUMIFS(水表!$C:$C,水表!$B:$B,X$3,水表!$A:$A,$B47) -> 0 | Y47: =SUMIFS(水表!$C:$C,水表!$B:$B,Y$3,水表!$A:$A,$B47) -> 1910.22 | Z47: =IF(SUM(W47:X47)<=0,0,SUM(W47:Y47)-SUM(W46:Y46)) -> 2 | AA47: =+P47 -> 11.319849 | AB47: =ROUND(Z47*AA47,2) -> 22.64
